<?xml version="1.0"?>
<robot>
    <macro name="link_left_wheel" params="name">
        <link name="${name}">
            <inertial>
              <mass value="10"/>
              <origin rpy="0 1.5707 1.5707" xyz="0 0 0"/>
              <inertia ixx="0.00044332" ixy="0" ixz="0" iyy="0.00044332" iyz="0" izz="0.00072"/>
            </inertial>
            <collision name="link_wheel_collision">
              <origin rpy="0 0 0" xyz="0 0 0"/>
              <geometry>
              <sphere radius="0.12"/>
              </geometry>
              <!-- <surface>
                <friction>
                  <ode>
                    <mu>1.0</mu>
                    <mu2>1.0</mu2>
                    <slip1>0.1</slip1>
                    <slip2>0.1</slip2>
                  </ode>
                </friction>
              </surface> -->
            </collision>
            <visual name="${name}_visual">
              <origin rpy="0 0 0" xyz="0 0 0"/>
              <geometry>
                <mesh filename="package://robot_cleaner/robot/meshes/wheels/omni_wheel_2.dae" />
              </geometry>
            </visual>
        </link>
    </macro>

    <macro name="joint_left_wheel" params="name child origin_xyz">
      <joint name="${name}" type="continuous">
        <origin rpy="0 0 0" xyz="${origin_xyz}"/>
        <child link="${child}"/>
        <parent link="link_chassis"/>
        <axis rpy="0 0 0" xyz="0 1 0"/>
        <!-- <limit effort="10000" velocity="1000"/>
        <joint_properties damping="100" friction="1000"/>
        <limit effort="1000.0" lower="-1e+16" upper="1e+16" velocity="3.5"/>
        <joint_properties damping="1.0" friction="1"/>  -->
      </joint>
    </macro>

 <macro name="link_right_wheel" params="name">
        <link name="${name}">
            <inertial>
              <mass value="10"/>
              <origin rpy="0 1.5707 1.5707" xyz="0 0 0"/>
              <inertia ixx="0.00044332" ixy="0" ixz="0" iyy="0.00044332" iyz="0" izz="0.00072"/>
            </inertial>
            <collision name="link_wheel_collision">
              <origin rpy="0 0 0" xyz="0 0 0"/>
              <geometry>
              <sphere radius="0.12"/>
              </geometry>
              <!-- <surface>
                <friction>
                  <ode>
                    <mu>1.0</mu>
                    <mu2>1.0</mu2>
                    <slip1>0.1</slip1>
                    <slip2>0.1</slip2>
                  </ode>
                </friction>
              </surface> -->
            </collision>
            <visual name="${name}_visual">
              <origin rpy="0 0 0" xyz="0 0 0"/>
              <geometry>
                <mesh filename="package://robot_cleaner/robot/meshes/wheels/omni_wheel_1.dae" />
              </geometry>
            </visual>
        </link>
    </macro>

    <macro name="joint_right_wheel" params="name child origin_xyz">
      <joint name="${name}" type="continuous">
        <origin rpy="0 0 0" xyz="${origin_xyz}"/>
        <child link="${child}"/>
        <parent link="link_chassis"/>
        <axis rpy="0 0 0" xyz="0 1 0"/>
         <!-- <limit effort="10000" velocity="1000"/>
        <joint_properties damping="100" friction="1000"/>
        <limit effort="1000.0" lower="-1e+16" upper="1e+16" velocity="3.5"/>
        <joint_properties damping="1.0" friction="1"/>  -->
      </joint>
    </macro>
</robot>
